<?xml version="1.0" ?>
<!-- ===================================================================================   -->
<!-- |    This document was autogenerated by xacro from /home/armstrong/catkin_ws/src/armstrong_hardware/robots/plover_unload_v0/urdf/robot.urdf.xacro   | -->
<!-- |    EDITING THIS FILE BY HAND IS NOT RECOMMENDED                                   | -->
<!-- ===================================================================================   -->
<robot name="xarm7">
  <material   name="left_Black">
    <color rgba="0.0 0.0 0.0 1.0"/>
  </material>
    <material name="left_Red">
    <color rgba="0.8 0.0 0.0 1.0"/>
  </material>
    <material name="left_White">
    <color rgba="1.0 1.0 1.0 1.0"/>
  </material>
    <material name="left_Silver">
    <color rgba="0.753 0.753 0.753 1.0"/>
    </material>
  <link name="left_link_base">
    <inertial>
      <origin   rpy="0 0 0" xyz="-0.021131 -0.0016302 0.056488"/>
      <mass value="0.88556"/>
      <inertia ixx="0.0030595" ixy="0.00012259" ixz="-0.00062705" iyy="0.0037783" iyz="0.00027023" izz="0.0020125"/>
    </inertial>
    <visual>
        <origin rpy="0 0 0" xyz="0 0 0"/>
      <geometry>
        <mesh filename="package://armstrong_hardware/meshes/xarm7_1305/visual/link_base/link_base.stl"/>
      </geometry>
      <material name="left_Silver"/>
    </visual>
      <collision>
      <origin rpy="0 0 0" xyz="0 0 0"/>
      <geometry>
          <mesh filename="package://armstrong_hardware/meshes/xarm7_1305/collision/link_base/padded_0.010m/meshes/part_0.stl"/>
      </geometry>
    </collision>
  </link>
  <link name="left_link1">
    <inertial>
      <origin rpy="0 0 0" xyz="-0.0042142 0.02821 -0.0087788"/>
      <mass value="0.42603"/>
      <inertia ixx="0.0014243" ixy="3.9946E-05" ixz="4.7078E-06" iyy="0.00123" iyz="-0.00026073" izz="0.00099229"/>
      </inertial>
    <visual>
      <origin rpy="0 0 0" xyz="0 0 0"/>
        <geometry>
        <mesh filename="package://armstrong_hardware/meshes/xarm7_1305/visual/link1/link1.stl"/>
      </geometry>
      <material name="left_White"/>
    </visual>
      <collision>
      <origin rpy="0 0 0" xyz="0 0 0"/>
      <geometry>
          <mesh filename="package://armstrong_hardware/meshes/xarm7_1305/collision/link1/padded_0.010m/meshes/part_0.stl"/>
      </geometry>
    </collision>
  </link>
  <joint name="unload_left_joint1" type="revolute">
    <origin rpy="-0.0019873378332704306 -0.002095351926982403   2.0820875761273783e-06" xyz="-0.001472343923524022 0.0002507121826056391 0.26507818698883057"/>
    <parent link="left_link_base"/>
    <child link="left_link1"/>
      <axis xyz="0 0 1"/>
    <limit effort="50" lower="-6.2517693806436885" upper="6.2517693806436885" velocity="3.14"/>
    <dynamics damping="10" friction="1"/>
  </joint>
  <link name="left_link2">
    <inertial>
        <origin rpy="0 0 0" xyz="-3.3178E-05 -0.12849 0.026337"/>
      <mass   value="0.56095"/>
      <inertia ixx="0.0031915" ixy="3.0892E-06" ixz="2.8729E-06" iyy="0.0017468" iyz="-0.0010241" izz="0.00235"/>
    </inertial>
      <visual>
      <origin rpy="0 0 0" xyz="0 0 0"/>
      <geometry>
          <mesh filename="package://armstrong_hardware/meshes/xarm7_1305/visual/link2/link2.stl"/>
      </geometry>
      <material name="left_White"/>
    </visual>
      <collision>
      <origin rpy="0 0 0" xyz="0 0 0"/>
      <geometry>
          <mesh filename="package://armstrong_hardware/meshes/xarm7_1305/collision/link2/padded_0.010m/meshes/part_0.stl"/>
      </geometry>
    </collision>
  </link>
  <joint name="unload_left_joint2" type="revolute">
    <origin rpy="-1.573082447052002 0.0020953973289579153   0.0003061577444896102" xyz="0.0005432970356196165 -0.00012371382035780698 2.828860488079954e-07"/>
    <parent link="left_link1"/>
    <child link="left_link2"/>
    <axis   xyz="0 0 1"/>
    <limit effort="50" lower="-1.97" upper="2.01" velocity="3.14"/>
    <dynamics damping="10" friction="1"/>
  </joint>
  <link name="left_link3">
    <inertial>
      <origin rpy="0 0 0" xyz="0.04223 -0.023258   -0.0096674"/>
      <mass value="0.44463"/>
      <inertia ixx="0.0011454" ixy="0.0001654" ixz="-0.0001951" iyy="0.0010503" iyz="0.00012027" izz="0.0011083"/>
    </inertial>
    <visual>
      <origin rpy="0 0 0" xyz="0 0 0"/>
      <geometry>
        <mesh filename="package://armstrong_hardware/meshes/xarm7_1305/visual/link3/link3.stl"/>
      </geometry>
      <material name="left_White"/>
    </visual>
      <collision>
      <origin rpy="0 0 0" xyz="0 0 0"/>
      <geometry>
          <mesh filename="package://armstrong_hardware/meshes/xarm7_1305/collision/link3/padded_0.010m/meshes/part_0.stl"/>
      </geometry>
    </collision>
  </link>
  <joint name="unload_left_joint3" type="revolute">
    <origin rpy="1.5750703811645508 0.000304074288578704   6.49816513487167e-07" xyz="-1.1413746960897697e-06 -0.29277151823043823 -0.0012513299006968737"/>
    <parent link="left_link2"/>
    <child link="left_link3"/>
    <axis   xyz="0 0 1"/>
    <limit effort="30" lower="-6.2517693806436885" upper="6.2517693806436885" velocity="3.14"/>
    <dynamics damping="5" friction="1"/>
  </joint>
  <link name="left_link4">
    <inertial>
      <origin rpy="0 0 0" xyz="0.067148 -0.10732 0.024479"/>
      <mass value="0.52387"/>
        <inertia ixx="0.0026033" ixy="0.00053379" ixz="0.00036314" iyy="0.0017649" iyz="-0.00083253" izz="0.0022431"/>
    </inertial>
    <visual>
        <origin rpy="0 0 0" xyz="0 0 0"/>
      <geometry>
        <mesh filename="package://armstrong_hardware/meshes/xarm7_1305/visual/link4/link4.stl"/>
        </geometry>
      <material name="left_White"/>
    </visual>
    <collision>
        <origin rpy="0 0 0" xyz="0 0 0"/>
      <geometry>
        <mesh filename="package://armstrong_hardware/meshes/xarm7_1305/collision/link4/padded_0.010m/meshes/part_0.stl"/>
      </geometry>
    </collision>
  </link>
  <joint name="unload_left_joint4" type="revolute">
    <origin rpy="1.5733860731124878 6.257488166738767e-06   -0.004832519218325615" xyz="0.053036171942949295 0.0007811266114003956 2.6869840894505614e-06"/>
    <parent link="left_link3"/>
    <child link="left_link4"/>
    <axis   xyz="0 0 1"/>
    <limit effort="30" lower="-0.1" upper="3.83" velocity="3.14"/>
    <dynamics damping="5" friction="1"/>
  </joint>
  <link name="left_link5">
    <inertial>
      <origin rpy="0 0 0" xyz="-0.00023397 0.036705   -0.080064"/>
      <mass value="0.18554"/>
      <inertia ixx="0.00099549" ixy="8.9957E-07" ixz="8.5285E-07" iyy="0.0008853" iyz="-0.00025682" izz="0.00035048"/>
    </inertial>
    <visual>
      <origin rpy="0 0 0" xyz="0 0 0"/>
      <geometry>
        <mesh filename="package://armstrong_hardware/meshes/xarm7_1305/visual/link5/link5.stl"/>
      </geometry>
      <material name="left_White"/>
    </visual>
      <collision>
      <origin rpy="0 0 0" xyz="0 0 0"/>
      <geometry>
          <mesh filename="package://armstrong_hardware/meshes/xarm7_1305/collision/link5/padded_0.010m/meshes/part_0.stl"/>
      </geometry>
    </collision>
  </link>
  <joint name="unload_left_joint5" type="revolute">
    <origin rpy="1.5703946352005005 0.004838994704186916   0.004323149099946022" xyz="0.07655718177556992 -0.34149888157844543 0.00013738837151322514"/>
    <parent link="left_link4"/>
    <child link="left_link5"/>
    <axis   xyz="0 0 1"/>
    <limit effort="30" lower="-6.2517693806436885" upper="6.2517693806436885" velocity="3.14"/>
    <dynamics damping="5" friction="1"/>
  </joint>
  <link name="left_link6">
    <inertial>
      <origin rpy="0 0 0" xyz="0.058911 0.028469 0.0068428"/>
      <mass value="0.31344"/>
        <inertia ixx="0.00052034" ixy="-0.00014989" ixz="0.00011658" iyy="0.00067968" iyz="6.116E-05" izz="0.00078345"/>
    </inertial>
    <visual>
        <origin rpy="0 0 0" xyz="0 0 0"/>
      <geometry>
        <mesh filename="package://armstrong_hardware/meshes/xarm7_1305/visual/link6/link6.stl"/>
        </geometry>
      <material name="left_White"/>
    </visual>
    <collision>
        <origin rpy="0 0 0" xyz="0 0 0"/>
      <geometry>
        <mesh filename="package://armstrong_hardware/meshes/xarm7_1305/collision/link6/padded_0.010m/meshes/part_0.stl"/>
      </geometry>
    </collision>
  </link>
  <joint name="unload_left_joint6" type="revolute">
    <origin rpy="1.5919177532196045 -0.004319444764405489   -0.0010413432028144598" xyz="-0.00032508408185094595 -0.0039029335603117943   -8.245369826909155e-05"/>
    <parent link="left_link5"/>
    <child link="left_link6"/>
    <axis xyz="0 0 1"/>
    <limit effort="20" lower="-1.67" upper="3.141592653589793" velocity="3.14"/>
    <dynamics damping="2" friction="1"/>
  </joint>
  <link name="left_link7">
    <inertial>
      <origin rpy="0 0 0" xyz="-1.5846E-05 -0.0046377 -0.012705"/>
      <mass value="0.31468"/>
      <inertia ixx="0.00016985" ixy="1.1102E-07" ixz="5.1075E-08" iyy="0.00011924" iyz="-2.1251E-06" izz="0.00026032"/>
    </inertial>
    <visual>
        <origin rpy="0 0 0" xyz="0 0 0"/>
      <geometry>
        <mesh filename="package://armstrong_hardware/meshes/xarm7_1305/visual/link7/link7.stl"/>
        </geometry>
      <material name="left_Silver"/>
    </visual>
    <collision>
        <origin rpy="0 0 0" xyz="0 0 0"/>
      <geometry>
        <mesh filename="package://armstrong_hardware/meshes/xarm7_1305/collision/link7/padded_0.010m/meshes/part_0.stl"/>
      </geometry>
    </collision>
  </link>
  <joint name="unload_left_joint7" type="revolute">
    <origin rpy="-1.5947668552398682 0.0005079025286249816   -0.000353742711013183" xyz="0.07720053941011429 0.0959256961941719 -0.002100581070408225"/>
    <parent link="left_link6"/>
    <child link="left_link7"/>
    <axis   xyz="0 0 1"/>
    <limit effort="20" lower="-6.2517693806436885" upper="6.2517693806436885" velocity="3.14"/>
    <dynamics damping="2" friction="1"/>
  </joint>
  <!-- tool0 is used to represent the UMI fingertip frame (poses output by the SLAM pipeline are in this frame) -->
  <!-- "The umi gripper finger tip frame in the default xarm tcp frame (which is just the center point at the end of the flange on link 7) is 247mm along the tcp z axis (I got this number from Sungbum)." -->
  <!-- xArm studio shows a 247mm z-axis offset as well as the -90 degree Z-axis rotation. This accounts for the length of both the Robotiq and UMI fingers -->
  <link name="left_tool0"/>
  <joint name="unload_left_link7-tool0_fixed_joint" type="fixed">
    <origin rpy="0 0 -1.5707963267948966" xyz="0 0 0.0247"/>
    <parent   link="left_link7"/>
    <child link="left_tool0"/>
  </joint>

</robot>


